Workbook

Sheet Dashboard 2026
A1: DASHBOARD DE CURSOS — 2026
A4: TOTAL DE CURSOS | D4: REALIZADOS | G4: A REALIZAR
A5: =COUNTIF('Ações InCompany'!B:B,2026) -> 20 | B5: cursos | D5: =COUNTIFS('Ações InCompany'!B:B,2026,'Ações InCompany'!C:C,"Realizado") -> 12 | E5: cursos | G5: =COUNTIFS('Ações InCompany'!B:B,2026,'Ações InCompany'!C:C,"A realizar") -> 8
A8: CURSOS REALIZADOS POR PÚBLICO-ALVO | D8: PARTICIPANTES POR PÚBLICO (REALIZADOS)
A10: Público-Alvo | B10: Qtd. Cursos | D10: Público | E10: Qtd. Participantes
A11: Servidores do TCDF | B11: =COUNTIFS('Ações InCompany'!B:B,2026,'Ações InCompany'!C:C,"Realizado",'Ações InCompany'!F:F,"Servidores do TCDF") -> 5 | D11: Servidores (P. Servidores) | E11: =SUMIFS('Ações InCompany'!O:O,'Ações InCompany'!B:B,2026,'Ações InCompany'!C:C,"Realizado") -> 202
A12: Jurisdicionados | B12: =COUNTIFS('Ações InCompany'!B:B,2026,'Ações InCompany'!C:C,"Realizado",'Ações InCompany'!F:F,"Jurisdicionados") -> 7 | D12: Jurisdicionados (P. Jurisdicionados) | E12: =SUMIFS('Ações InCompany'!P:P,'Ações InCompany'!B:B,2026,'Ações InCompany'!C:C,"Realizado") -> 321
A13: Sociedade | B13: =COUNTIFS('Ações InCompany'!B:B,2026,'Ações InCompany'!C:C,"Realizado",'Ações InCompany'!F:F,"Sociedade") -> 0 | D13: Sociedade (P. Sociedade) | E13: =SUMIFS('Ações InCompany'!Q:Q,'Ações InCompany'!B:B,2026,'Ações InCompany'!C:C,"Realizado") -> 73
A14: TOTAL | B14: =SUM(B11:B13) -> 12 | D14: TOTAL GERAL | E14: =SUM(E11:E13) -> 596
A30: CURSOS POR PROGRAMA (TODOS OS STATUS)
A32: Programa | B32: Realizados | C32: A Realizar | D32: Total | E32: % do Total
A33: Treinamento de Jurisdicionados | B33: =COUNTIFS('Ações InCompany'!B:B,2026,'Ações InCompany'!C:C,"Realizado",'Ações InCompany'!G:G,A33) -> 8 | C33: =COUNTIFS('Ações InCompany'!B:B,2026,'Ações InCompany'!C:C,"A realizar",'Ações InCompany'!G:G,A33) -> 1 | D33: =B33+C33 -> 9 | E33: =D33/$D$41 -> 0.45
A34: Administração, Estratégia e Inovação | B34: =COUNTIFS('Ações InCompany'!B:B,2026,'Ações InCompany'!C:C,"Realizado",'Ações InCompany'!G:G,A34) -> 1 | C34: =COUNTIFS('Ações InCompany'!B:B,2026,'Ações InCompany'!C:C,"A realizar",'Ações InCompany'!G:G,A34) -> 2 | D34: =B34+C34 -> 3 | E34: =D34/$D$41 -> 0.15
A35: Inteligência Artificial e Análise de Dados | B35: =COUNTIFS('Ações InCompany'!B:B,2026,'Ações InCompany'!C:C,"Realizado",'Ações InCompany'!G:G,A35) -> 1 | C35: =COUNTIFS('Ações InCompany'!B:B,2026,'Ações InCompany'!C:C,"A realizar",'Ações InCompany'!G:G,A35) -> 1 | D35: =B35+C35 -> 2 | E35: =D35/$D$41 -> 0.1
A36: Escola de Instrutores | B36: =COUNTIFS('Ações InCompany'!B:B,2026,'Ações InCompany'!C:C,"Realizado",'Ações InCompany'!G:G,A36) -> 1 | C36: =COUNTIFS('Ações InCompany'!B:B,2026,'Ações InCompany'!C:C,"A realizar",'Ações InCompany'!G:G,A36) -> 0 | D36: =B36+C36 -> 1 | E36: =D36/$D$41 -> 0.05
A37: Desenvolvimento Individual e Promoção da Cultura Organizacional | B37: =COUNTIFS('Ações InCompany'!B:B,2026,'Ações InCompany'!C:C,"Realizado",'Ações InCompany'!G:G,A37) -> 1 | C37: =COUNTIFS('Ações InCompany'!B:B,2026,'Ações InCompany'!C:C,"A realizar",'Ações InCompany'!G:G,A37) -> 1 | D37: =B37+C37 -> 2 | E37: =D37/$D$41 -> 0.1
A38: Formação de Controladores sociais e cidadãos | B38: =COUNTIFS('Ações InCompany'!B:B,2026,'Ações InCompany'!C:C,"Realizado",'Ações InCompany'!G:G,A38) -> 0 | C38: =COUNTIFS('Ações InCompany'!B:B,2026,'Ações InCompany'!C:C,"A realizar",'Ações InCompany'!G:G,A38) -> 2 | D38: =B38+C38 -> 2 | E38: =D38/$D$41 -> 0.1
A39: Metodologias de Auditoria e Fiscalização | B39: =COUNTIFS('Ações InCompany'!B:B,2026,'Ações InCompany'!C:C,"Realizado",'Ações InCompany'!G:G,A39) -> 0 | C39: =COUNTIFS('Ações InCompany'!B:B,2026,'Ações InCompany'!C:C,"A realizar",'Ações InCompany'!G:G,A39) -> 1 | D39: =B39+C39 -> 1 | E39: =D39/$D$41 -> 0.05
A40: (Sem Programa) | B40: =COUNTIFS('Ações InCompany'!B:B,2026,'Ações InCompany'!C:C,"Realizado",'Ações InCompany'!G:G,"") -> 0 | C40: =COUNTIFS('Ações InCompany'!B:B,2026,'Ações InCompany'!C:C,"A realizar",'Ações InCompany'!G:G,"") -> 0 | D40: =B40+C40 -> 0 | E40: =D40/$D$41 -> 0
A41: TOTAL | B41: =SUM(B33:B40) -> 12 | C41: =SUM(C33:C40) -> 8 | D41: =SUM(D33:D40) -> 20 | E41: =SUM(E33:E40) -> 1

Sheet Dashboard 2025
A1: DASHBOARD DE CURSOS REALIZADOS — 2025
A4: TOTAL DE CURSOS REALIZADOS | D4: TOTAL DE PARTICIPANTES
A5: =COUNTIFS('Ações InCompany'!B:B,2025,'Ações InCompany'!C:C,"Realizado") -> 120 | B5: cursos | D5: =SUMIFS('Ações InCompany'!R:R,'Ações InCompany'!B:B,2025,'Ações InCompany'!C:C,"Realizado") -> 6029 | E5: participantes
A7: CURSOS POR PÚBLICO-ALVO | D7: PARTICIPANTES POR PÚBLICO
A9: Público-Alvo | B9: Qtd. Cursos | D9: Público | E9: Qtd. Participantes
A10: Servidores do TCDF | B10: =COUNTIFS('Ações InCompany'!B:B,2025,'Ações InCompany'!C:C,"Realizado",'Ações InCompany'!F:F,"Servidores do TCDF") -> 61 | D10: Servidores (P. Servidores) | E10: =SUMIFS('Ações InCompany'!O:O,'Ações InCompany'!B:B,2025,'Ações InCompany'!C:C,"Realizado") -> 2649
A11: Jurisdicionados | B11: =COUNTIFS('Ações InCompany'!B:B,2025,'Ações InCompany'!C:C,"Realizado",'Ações InCompany'!F:F,"Jurisdicionados") -> 31 | D11: Jurisdicionados (P. Jurisdicionados) | E11: =SUMIFS('Ações InCompany'!P:P,'Ações InCompany'!B:B,2025,'Ações InCompany'!C:C,"Realizado") -> 2140
A12: Sociedade | B12: =COUNTIFS('Ações InCompany'!B:B,2025,'Ações InCompany'!C:C,"Realizado",'Ações InCompany'!F:F,"Sociedade") -> 28 | D12: Sociedade (P. Sociedade) | E12: =SUMIFS('Ações InCompany'!Q:Q,'Ações InCompany'!B:B,2025,'Ações InCompany'!C:C,"Realizado") -> 1240
A13: TOTAL | B13: =SUM(B10:B12) -> 120 | D13: TOTAL GERAL | E13: =SUM(E10:E12) -> 6029
A29: CURSOS POR PROGRAMA
A31: Programa | B31: Qtd. Cursos | C31: % do Total
A32: Treinamento de Jurisdicionados | B32: =COUNTIFS('Ações InCompany'!B:B,2025,'Ações InCompany'!C:C,"Realizado",'Ações InCompany'!G:G,A32) -> 57 | C32: =B32/$B$42 -> 0.475
A33: Administração, Estratégia e Inovação | B33: =COUNTIFS('Ações InCompany'!B:B,2025,'Ações InCompany'!C:C,"Realizado",'Ações InCompany'!G:G,A33) -> 16 | C33: =B33/$B$42 -> 0.13333333
A34: Desenvolvimento Individual e Promoção da Cultura Organizacional | B34: =COUNTIFS('Ações InCompany'!B:B,2025,'Ações InCompany'!C:C,"Realizado",'Ações InCompany'!G:G,A34) -> 16 | C34: =B34/$B$42 -> 0.13333333
A35: Áreas Temáticas de Fiscalização do Setor Público | B35: =COUNTIFS('Ações InCompany'!B:B,2025,'Ações InCompany'!C:C,"Realizado",'Ações InCompany'!G:G,A35) -> 8 | C35: =B35/$B$42 -> 0.066666667
A36: Mineração e Análise de Dados | B36: =COUNTIFS('Ações InCompany'!B:B,2025,'Ações InCompany'!C:C,"Realizado",'Ações InCompany'!G:G,A36) -> 9 | C36: =B36/$B$42 -> 0.075
A37: Metodologias de Auditoria e Fiscalização | B37: =COUNTIFS('Ações InCompany'!B:B,2025,'Ações InCompany'!C:C,"Realizado",'Ações InCompany'!G:G,A37) -> 6 | C37: =B37/$B$42 -> 0.05
A38: Ambientação e Desenvolvimento na Carreira | B38: =COUNTIFS('Ações InCompany'!B:B,2025,'Ações InCompany'!C:C,"Realizado",'Ações InCompany'!G:G,A38) -> 4 | C38: =B38/$B$42 -> 0.033333333
A39: Avaliação de Políticas Públicas | B39: =COUNTIFS('Ações InCompany'!B:B,2025,'Ações InCompany'!C:C,"Realizado",'Ações InCompany'!G:G,A39) -> 2 | C39: =B39/$B$42 -> 0.016666667
A40: Desenvolvimento Gerencial | B40: =COUNTIFS('Ações InCompany'!B:B,2025,'Ações InCompany'!C:C,"Realizado",'Ações InCompany'!G:G,A40) -> 2 | C40: =B40/$B$42 -> 0.016666667
A41: (Sem Programa) | B41: =COUNTIFS('Ações InCompany'!B:B,2025,'Ações InCompany'!C:C,"Realizado",'Ações InCompany'!G:G,"") -> 0 | C41: =B41/$B$42 -> 0
A42: TOTAL | B42: =SUM(B32:B41) -> 120 | C42: =SUM(C32:C41) -> 1

Sheet PlanoCap
A1: ANO - VIGÊNCIA | B1: EIXO TEMÁTICO | C1: Programa | D1: Público-Alvo Preferencial | E1: Descrição
A2: 2024/2025 | B2: Controle Externo | C2: Avaliação de Políticas Públicas | D2: Membros e servidores que atuam no Controle Externo | E2: Destina-se a oferecer ações de aprendizagem de metodologias necessárias à avaliação de políticas públicas governamentais.
A3: 2024/2025 | B3: Controle Externo | C3: Metodologias de Auditoria e Fiscalização | D3: Membros e servidores que atuam no Controle Externo | E3: Destina-se a oferecer ações de aprendizagem de metodologias necessárias à realização de fiscalizações governamentais, alinhadas às Normas Brasileiras de Auditoria do Setor Público.
A4: 2024/2025 | B4: Controle Externo | C4: Áreas Temáticas de Fiscalização do Setor Público | D4: Membros e servidores que atuam no Controle Externo | E4: Destina-se a oferecer ações de aprendizagem voltadas às áreas temáticas fiscalizadas, como saúde, pessoal, previdência, assistência social, obras e serviços de engenharia, tecnologia de informação e comunicação, licitações e contratos, parcerias público-privadas, concessões e desestatização, entre outros
A5: 2024/2025 | B5: Controle Externo | C5: Treinamento de Jurisdicionados | D5: Servidores Públicos dos órgãos jurisdicionados ao TCDF | E5: Destina-se a oferecer ações de aprendizagem para os gestores e servidores públicos dos órgãos jurisdicionados ao TCDF, a fim de promover a correta e eficiente aplicação dos recursos públicos
A6: 2024/2025 | B6: Controle Externo | C6: Formação de Controladores sociais e cidadãos | D6: Representantes de entidades de Controle social e Cidadãos | E6: Destina-se a oferecer ações de aprendizagem para os cidadãos, para fomentar o exercício do controle social.
A7: 2024/2025 | B7: Organizacional | C7: Mineração e Análise de Dados | D7: Servidores que possam utilizar análise de dados no desempenho de suas atividades | E7: Destina-se a oferecer ações de aprendizagem voltadas à análise e mineração de dados, a fim de identificar informações úteis à tomada de decisão em meio a grandes quantidades de dados.
A8: 2024/2025 | B8: Organizacional | C8: Administração, Estratégia e Inovação | D8: Membros e Servidores do TCDF | E8: Destina-se a oferecer ações de aprendizagem para auxiliar na gestão e apoio estratégico do TCDF, assim como promover a inovação na Casa. As ações buscam aprimorar processos como os de planejamento, gestão de pessoas, gestão da informação, gestão de projetos, gestão de processos, gestão administrativa, gestão contratual, relacionamento com o cliente, operacionalização de sistemas, entre outros
A9: 2024/2025 | B9: Programas Transversais | C9: Desenvolvimento Gerencial | D9: Servidores que ocupam função gerencial e potenciais líderes a desenvolver | E9: Destina-se a oferecer ações de aprendizagem para os atuais dirigentes do TCDF, considerando as necessidades de cada nível gerencial (estratégico, tático e operacional), àqueles que assumem funções gerenciais e os servidores com potencial de atuação gerencial no TCDF. As ações devem auxiliar os gestores no exercício da função gerencial, aprimorando competências relacionadas à gestão de desempenho, ao desenvolvimento da equipe, gestão da equipe remota e/ou híbrida, orientação estratégica, feedback, entre outros.
A10: 2024/2025 | B10: Programas Transversais | C10: Desenvolvimento Individual e Promoção da Cultura Organizacional | D10: Servidores do TCDF | E10: Destina-se a oferecer ações de aprendizagem para auxiliar no desenvolvimento de competências funcionais dos servidores, tais quais orientação para resultado, ética e relacionamento interpessoal.
A11: 2024/2025 | B11: Programas Transversais | C11: Ambientação e Desenvolvimento na Carreira | D11: Servidores do TCDF | E11: Destina-se a oferecer ações de aprendizagem para auxiliar na ambientação e promoção de servidores, promovendo a visão sistêmica da sua atuação no âmbito do TCDF

Sheet Validação Dados
A1: Público-alvo | B1: Modalidade | C1: Previsão | D1: Status
A2: Servidores do TCDF | B2: Instrutoria Interna | C2: Previsto | D2: A realizar
A3: Jurisdicionados | B3: Instrutoria Externa | C3: Solicitado | D3: Em andamento
A4: Sociedade | B4: Híbrida | D4: Cancelado
A5: Híbrido | D5: Realizado
D6: Adiado

Sheet Ações InCompany
A1: ID | B1: Ano | C1: Status Evento | D1: Processo | E1: Curso | F1: Público-Alvo | G1: Programa | H1: Data TXT | I1: Início | J1: Término | K1: Modalidade | L1: Valor instrutoria | M1: Nota Av. Reação | N1: Qtd Vagas | O1: P. Servidores | P1: P. Jurisdicionados | Q1: P. Sociedade | R1: Total Part. | S1: C.H. | T1: Instrutor
A2: 2014-001 | B2: 2014 | C2: Realizado | E2: CURSO DE ELABORAÇÃO DE PARECERES E RELATÓRIOS | F2: Servidores do TCDF | G2: Metodologias de Auditoria e Fiscalização | H2: 17 a 21/03/2014 | I2: 41715 | J2: 41719 | K2: Instrutoria Externa | L2: 19500 | O2: 20 | R2: =SUM(O2:Q2) -> 20 | S2: 20
A3: 2014-002 | B3: 2014 | C3: Realizado | E3: ELABORAÇÃO DE PLANO DE AUDITORIA E MATRIZ DE PLANEJAMENTO | F3: Servidores do TCDF | G3: Metodologias de Auditoria e Fiscalização | H3: 14 e 14/04/2014 | I3: 41743 | J3: 41744 | K3: Instrutoria Externa | L3: 28000 | O3: 16 | R3: =SUM(O3:Q3) -> 16 | S3: 16
A4: 2014-003 | B4: 2014 | C4: Realizado | E4: CURSO DE EXCEL AVANÇADO | F4: Servidores do TCDF | G4: Mineração e Análise de Dados | H4: 02 a 09/06/2014 | I4: 41792 | J4: 41799 | K4: Instrutoria Interna | L4: 2991 | O4: 24 | R4: =SUM(O4:Q4) -> 24 | S4: 24
A5: 2014-004 | B5: 2014 | C5: Realizado | E5: REGIME DIFERENCIADO DE CONTRATAÇÕES PÚBLICAS - RDC | F5: Servidores do TCDF | G5: Administração, Estratégia e Inovação | H5: 24 e 25/06/2014 | I5: 41814 | J5: 41815 | K5: Instrutoria Externa | L5: 41341.16 | O5: 16 | R5: =SUM(O5:Q5) -> 16 | S5: 16
A6: 2014-005 | B6: 2014 | C6: Realizado | E6: ENGENHARIA ECONÔMICA I E II - CAPACITAÇÃO EM PARCERIAS PÚBLICO PRIVADAS E CONCESSÕES DE | F6: Servidores do TCDF | G6: Metodologias de Auditoria e Fiscalização | H6: 04 a 08/08/2014 | I6: 41855 | J6: 41859 | K6: Instrutoria Externa | L6: 54900 | O6: 40 | R6: =SUM(O6:Q6) -> 40 | S6: 40
A7: 2014-006 | B7: 2014 | C7: Realizado | E7: CURSO TÉCNICAS DE AUDITORIA OPERACIONAL | F7: Servidores do TCDF | G7: Metodologias de Auditoria e Fiscalização | H7: 10/09/2014 | I7: 41892 | J7: 41892 | K7: Instrutoria Externa | L7: 15000 | O7: 30 | R7: =SUM(O7:Q7) -> 30 | S7: 30
A8: 2014-007 | B8: 2014 | C8: Realizado | F8: Servidores do TCDF | G8: Metodologias de Auditoria e Fiscalização | H8: 31/10/2014 | I8: 41943 | J8: 41943 | K8: Instrutoria Externa | L8: 33260 | O8: 24 | R8: =SUM(O8:Q8) -> 24 | S8: 24
A9: 2014-008 | B9: 2014 | C9: Realizado | E9: PROCESSO DE CONTRATAÇÃO PÚBLICA | F9: Servidores do TCDF | G9: Administração, Estratégia e Inovação | H9: 10 a 14/11/2014 | I9: 41953 | J9: 41957 | K9: Instrutoria Interna | L9: 4353.54 | P9: 37 | R9: =SUM(O9:Q9) -> 37 | S9: 8
A10: 2014-009 | B10: 2014 | C10: Realizado | E10: TERMO DE REFERÊNCIA DE SERVIÇOS CONTINUADOS COM DEDICAÇÃO EXCLUSIVA DE MÃO DE OBRA | F10: Servidores do TCDF | G10: Metodologias de Auditoria e Fiscalização | H10: 24 a 28/11/2014 | I10: 41967 | J10: 41971 | K10: Instrutoria Interna | L10: 4353.54 | P10: 58 | R10: =SUM(O10:Q10) -> 58 | S10: 20
A11: 2015-001 | B11: 2015 | C11: Realizado | D11: 1683/2015 | E11: ELABORAÇÃO DE PARECERES E RELATÓRIOS | F11: Servidores do TCDF | G11: Metodologias de Auditoria e Fiscalização | H11: 23 a 27/03/2015 | I11: 42086 | J11: 42090 | K11: Instrutoria Externa | L11: 23500 | O11: 25 | R11: =SUM(O11:Q11) -> 25 | S11: 20 | T11: José Paulo Moreira de Oliveira
A12: 2015-002 | B12: 2015 | C12: Realizado | D12: 3716/2015 | E12: O PROCESSO DE CONTRATAÇÃO PÚBLICA | F12: Jurisdicionados | G12: Administração, Estratégia e Inovação | H12: 06 a 10/04/2015 | I12: 42100 | J12: 42104 | K12: Instrutoria Interna | L12: 4992.74 | P12: 85 | R12: =SUM(O12:Q12) -> 85 | S12: 20 | T12: Amauri Alves Nery
A13: 2015-003 | B13: 2015 | C13: Realizado | D13: 5891/2015 | E13: AUDITORIA EM OBRAS RODOVIÁRIAS | F13: Servidores do TCDF | G13: Áreas Temáticas de Fiscalização do Setor Público | H13: 06 a 10/04/2015 | I13: 42100 | J13: 42104 | K13: Instrutoria Externa | L13: 29000 | O13: 19 | R13: =SUM(O13:Q13) -> 19 | S13: 40 | T13: Elci Pessoa Júnior
A14: 2015-004 | B14: 2015 | C14: Realizado | D14: 2515/2015 | E14: TERMO DE REFERÊNCIA DE SERVIÇOS CONTINUADOS COM DEDICAÇÃO EXCLUSIVA DE MÃO DE OBRA | F14: Jurisdicionados | G14: Treinamento de Jurisdicionados | H14: 13 a 17/04/2015 | I14: 42107 | J14: 42111 | K14: Instrutoria Interna | L14: 4447.52 | P14: 89 | R14: =SUM(O14:Q14) -> 89 | S14: 20 | T14: Leonardo José Alves Leal Neri
A15: 2015-005 | B15: 2015 | C15: Realizado | D15: 7690/2015 | E15: FISCALIZAÇÃO DE CONTRATOS ADMINISTRATIVOS | F15: Servidores do TCDF | G15: Administração, Estratégia e Inovação | H15: 16, 17, 22, 23 e 24/04/2020 | I15: 42110 | J15: 42118 | K15: Instrutoria Interna | L15: 4447.52 | O15: 37 | R15: =SUM(O15:Q15) -> 37 | S15: 30 | T15: Leonardo José Alves Leal Neri
A16: 2015-006 | B16: 2015 | C16: Realizado | E16: PALESTRA CONSELHOS REGIONAIS DE SAÚDE | F16: Sociedade | G16: N/A | I16: 42122 | J16: 42122 | K16: Instrutoria Interna | L16: 0 | O16: 0 | P16: 0 | Q16: 0 | R16: =SUM(O16:Q16) -> 0 | S16: 5
A17: 2015-007 | B17: 2015 | C17: Realizado | D17: 3481/2015 | E17: PROCESSO NOS TRIBUNAIS DE CONTAS | F17: Servidores do TCDF | G17: Metodologias de Auditoria e Fiscalização | H17: 26 a 29/05/2015 | I17: 42129 | J17: 42132 | K17: Instrutoria Externa | L17: 35500 | O17: 30 | R17: =SUM(O17:Q17) -> 30 | S17: 16 | T17: Odilon Cavallari de Oliveira
A18: 2015-008 | B18: 2015 | C18: Realizado | D18: 5654/2015 | E18: A NOVA CONTABILIDADE APLICADA AO SETOR PÚBLICO | F18: Servidores do TCDF | G18: Administração, Estratégia e Inovação | H18: 11 a 15/05/2015 | I18: 42135 | J18: 42139 | K18: Instrutoria Interna | L18: 4992.74 | O18: 30 | R18: =SUM(O18:Q18) -> 30 | S18: 20 | T18: Romildo Araújo da Silva
A19: 2015-009 | B19: 2015 | C19: Realizado | D19: 14060/2015 | E19: TREINAMENTO DO SISTEMA TERRAGEO | F19: Servidores do TCDF | G19: Administração, Estratégia e Inovação | H19: 22/05/2015 | I19: 42146 | J19: 42146 | K19: Instrutoria Externa | L19: 0 | O19: 15 | R19: =SUM(O19:Q19) -> 15 | S19: 8 | T19: INSTRUTOR EXTERNO TERRACAP
A20: 2015-010 | B20: 2015 | C20: Realizado | D20: 1098/2015 | E20: EXCEL AVANÇADO | F20: Servidores do TCDF | G20: Mineração e Análise de Dados | H20: 25/05 a 01/06/2015 | I20: 42149 | J20: 42156 | K20: Instrutoria Externa | L20: 2630 | O20: 14 | R20: =SUM(O20:Q20) -> 14 | S20: 24 | T20: Logus TI
A21: 2015-011 | B21: 2015 | C21: Realizado | D21: 12742/2015 | E21: TREINAMENTO SIGGO (Sistema Integrado de Contabilidade Governamental) | F21: Servidores do TCDF | G21: Administração, Estratégia e Inovação | H21: 08 a 12/06/2015 | I21: 42163 | J21: 42167 | K21: Instrutoria Interna | L21: 0 | O21: 14 | R21: =SUM(O21:Q21) -> 14 | S21: 20 | T21: Rômulo Miranda Alvim
A22: 2015-012 | B22: 2015 | C22: Realizado | D22: 13480/2015 | E22: GESTÃO E FISCALIZAÇÃO DE CONTRATOS ADMINISTRATIVOS - MÓDULO I | F22: Jurisdicionados | G22: Treinamento de Jurisdicionados | H22: 15 a 19/06/2015 | I22: 42170 | J22: 42174 | K22: Instrutoria Interna | L22: 4447.52 | P22: 49 | R22: =SUM(O22:Q22) -> 49 | S22: 20 | T22: Roberto Dias Santiago
A23: 2015-013 | B23: 2015 | C23: Realizado | D23: 19283/2015 | E23: SEMINÁRIO ATUALIZAÇÃO EM LEGISLAÇÃO DE PESSOAL | F23: Servidores do TCDF | G23: Administração, Estratégia e Inovação | H23: 05 e 07/08/2015 | I23: 42221 | J23: 42223 | K23: Instrutoria Interna | L23: 0 | O23: 43 | R23: =SUM(O23:Q23) -> 43 | S23: 8 | T23: Inácio Magalhães Filho
A24: 2015-014 | B24: 2015 | C24: Realizado | D24: 22314/2015 | E24: METODOLOGIA DE CONSTRUÇÃO E ATUALIZAÇÃO DO TESAURO DE CONTAS DO DF | F24: Servidores do TCDF | G24: Mineração e Análise de Dados | H24: 24 a 28/08/2015 | I24: 42240 | J24: 42244 | K24: Instrutoria Interna | L24: 2702.38 | O24: 25 | R24: =SUM(O24:Q24) -> 25 | S24: 20 | T24: ANDREA FORTALEZA BRANDES DE SOUZA
A25: 2015-015 | B25: 2015 | C25: Realizado | D25: 17949/2015 | E25: RESPONSABILIDADE DE AGENTES PÚBLICOS E PRIVADOS PERANTE OS TRIBUNAIS DE CONTAS | F25: Servidores do TCDF | G25: Treinamento de Jurisdicionados | H25: 31/08/2015 a 04/09/2015 | I25: 42247 | J25: 42251 | K25: Instrutoria Externa | L25: 33600 | O25: 35 | R25: =SUM(O25:Q25) -> 35 | S25: 20 | T25: Aprimora Treinamentos
A26: 2015-016 | B26: 2015 | C26: Realizado | D26: 23973/2015 | E26: TÉCNICAS DE AUDITORIA OPERACIONAL | F26: Servidores do TCDF | G26: Metodologias de Auditoria e Fiscalização | H26: 14 a 18/09/2015 | I26: 42261 | J26: 42265 | K26: Instrutoria Externa | L26: 15000 | O26: 35 | R26: =SUM(O26:Q26) -> 35 | S26: 25 | T26: Dagomar Henrique Limas
A27: 2015-017 | B27: 2015 | C27: Realizado | E27: LEGISLAÇÃO DE PESSOAL NO SETOR PÚBLICO COM ENFOQUE NA LC nº 840/2011 | F27: Jurisdicionados | G27: N/A | I27: 42268 | J27: 42272 | K27: Instrutoria Interna | L27: 4447.52 | O27: 87 | R27: =SUM(O27:Q27) -> 87
A28: 2015-018 | B28: 2015 | C28: Realizado | D28: 29327/2015 | E28: CAPACITAÇÃO PARA CONSELHEIROS DE SAÚDE - Turma I | F28: Sociedade | G28: Treinamento de Jurisdicionados | H28: 29/09/2015 a 02/10/2015 | I28: 42276 | J28: 42279 | K28: Instrutoria Interna | L28: 4076.52 | Q28: 46 | R28: =SUM(O28:Q28) -> 46 | S28: 20 | T28: Romildo Araújo da Silva; Tarsila Firmino Ely
A29: 2015-019 | B29: 2015 | C29: Realizado | D29: 30040/2015 | E29: OFICINA DE ACCESS AVANÇADO | F29: Servidores do TCDF | G29: Mineração e Análise de Dados | H29: 05 a 09/10/2015 | I29: 42282 | J29: 42286 | K29: Instrutoria Interna | L29: 4447.52 | O29: 15 | R29: =SUM(O29:Q29) -> 15 | S29: 20 | T29: JOSDEYVI MAGALHAES RUSSI
A30: 2015-020 | B30: 2015 | C30: Realizado | D30: 13480/2015 | E30: GESTÃO E FISCALIZAÇÃO DE CONTRATOS ADMINISTRATIVOS - MÓDULO II | F30: Jurisdicionados | G30: Treinamento de Jurisdicionados | H30: 19 a 23/10/2015 | I30: 42296 | J30: 42300 | K30: Instrutoria Interna | L30: 4447.52 | P30: 54 | R30: =SUM(O30:Q30) -> 54 | S30: 20 | T30: Roberto Dias Santiago
A31: 2015-021 | B31: 2015 | C31: Realizado | E31: CONTRATAÇÃO DE SOLUÇÕES DE TECNOLOGIA DA INFORMAÇÃO E COMUNICAÇÃO - IN nº 04/2014 | F31: Jurisdicionados | G31: N/A | I31: 42303 | J31: 42305 | K31: Instrutoria Interna | L31: 4447.52 | O31: 52 | R31: =SUM(O31:Q31) -> 52 | S31: 0
A32: 2015-022 | B32: 2015 | C32: Realizado | D32: 29327/2015 | E32: CAPACITAÇÃO PARA CONSELHEIROS DE SAÚDE - Turma II | F32: Sociedade | G32: Treinamento de Jurisdicionados | H32: 17 a 20/11/2015 | I32: 42325 | J32: 42328 | K32: Instrutoria Interna | L32: 4076.52 | Q32: 46 | R32: =SUM(O32:Q32) -> 46 | S32: 20 | T32: Romildo Araújo da Silva; Tarsila Firmino Ely
A33: 2016-001 | B33: 2016 | C33: Realizado | D33: 13946/2016 | E33: Sistema Channel - Turma 1 | F33: Servidores do TCDF | G33: N/A | I33: 42495 | K33: Instrutoria Externa | L33: 0 | O33: 14 | R33: =SUM(O33:Q33) -> 14 | S33: 8 | T33: Breno
A34: 2016-002 | B34: 2016 | C34: Realizado | E34: Instrutoria | F34: Servidores do TCDF | G34: N/A | I34: 42495 | K34: Instrutoria Externa | L34: 22500 | O34: 25 | R34: =SUM(O34:Q34) -> 25 | S34: 20
A35: 2016-003 | B35: 2016 | C35: Realizado | D35: 30532/2016; 28880/2016 | E35: Trilhas de Aprendizagem | F35: Servidores do TCDF | G35: N/A | I35: 42495 | K35: Instrutoria Externa | L35: 25200 | O35: 17 | R35: =SUM(O35:Q35) -> 17 | S35: 20 | T35: Pedro Paulo Carbone; Sylvio Maestrelli; Anelise Pereira Sihler
A36: 2016-004 | B36: 2016 | C36: Realizado | D36: 8721/2016 | E36: Termo de Referência de Serviços Continuados com dedicação exclusiva de mão de obra | F36: Jurisdicionados | G36: Treinamento de Jurisdicionados | H36: 16 a 20/05/2016 | I36: 42506 | J36: 42510 | K36: Instrutoria Interna | L36: 6671.48 | P36: 75 | R36: =SUM(O36:Q36) -> 75 | S36: 20 | T36: Leonardo José Alves Leal Neri
A37: 2016-005 | B37: 2016 | C37: Realizado | D37: 16866/2016 | E37: Workshop para prefeitos comunitários | F37: Sociedade | G37: Treinamento de Jurisdicionados | H37: 13/06/2016 | I37: 42534 | J37: 42534 | K37: Instrutoria Interna | L37: 2668.6 | P37: 18 | R37: =SUM(O37:Q37) -> 18 | S37: 3 | T37: LUIZ GENEDIO MENDES JORGE
A38: 2016-006 | B38: 2016 | C38: Realizado | D38: 8195/2016 | E38: Workshop sobre Parcerias Público-Privadas | F38: Sociedade | G38: Treinamento de Jurisdicionados | H38: 13 e 14/06/2016 | I38: 42534 | J38: 42535 | K38: Instrutoria Externa | L38: 0 | O38: 33 | R38: =SUM(O38:Q38) -> 33 | S38: 10 | T38: Maria Aparecida Aiko Ikemura
A39: 2016-007 | B39: 2016 | C39: Realizado | D39: 12356/2016 | E39: Contratação Direta - Dispensa e Inexigibilidade de Licitação | F39: Jurisdicionados | G39: Treinamento de Jurisdicionados | H39: 13 a 17/06/2016 | I39: 42534 | J39: 42538 | K39: Instrutoria Interna | L39: 6671.48 | P39: 55 | R39: =SUM(O39:Q39) -> 55 | S39: 20 | T39: Roberto Dias Santiago
A40: 2016-008 | B40: 2016 | C40: Realizado | D40: 16351/2016 | E40: Capacitação para Conselheiros de Saúde | F40: Sociedade | G40: Metodologias de Auditoria e Fiscalização | H40: 27/06/2016 a 01/07/2016 | I40: 42548 | J40: 42552 | K40: Instrutoria Interna | L40: 7080.23 | Q40: 45 | R40: =SUM(O40:Q40) -> 45 | S40: 20 | T40: ROMILDO ARAUJO DA SILVA; TARSILA FIRMINO ELY
...

Sheet GECC 2026
A1: Ano | B1: ID Ação | C1: Status | D1: Curso | E1: Carga Horária | F1: Instrutor | G1: Qtd Instrutores | H1: GECC Aula (h) | I1: GECC Material (h) | J1: Total GECC (h) | L1: Ano Filtro: | M1: 2026 | U1: Override Aula (h) | V1: Override Material (h)
A2: {=_xlfn.LET(_xlpm.totalRows,MAX(S4:S200),_xlpm.seq,_xlfn.SEQUENCE(_xlpm.totalRows),_xlpm.srcRow,_xlfn.MAP(_xlpm.seq,_xlfn.LAMBDA(_xlpm.s,MATCH(_xlpm.s-1,T4:T200,1))),_xlpm.instrIdx,_xlfn.MAP(_xlpm.seq,_xlpm.srcRow,_xlfn.LAMBDA(_xlpm.s,_xlpm.sr,_xlpm.s-INDEX(T4:T200,_xlpm.sr))),_xlpm.ano,_xlfn.MAP(_xlpm.srcRow,_xlfn.LAMBDA(_xlpm.sr,INDEX(L4:L200,_xlpm.sr))),_xlpm.id,_xlfn.MAP(_xlpm.srcRow,_xlfn.LAMBDA(_xlpm.sr,INDEX(M4:M200,_xlpm.sr))),_xlpm.status,_xlfn.MAP(_xlpm.srcRow,_xlfn.LAMBDA(_xlpm.sr,INDEX(N4:N200,_xlpm.sr))),_xlpm.curso,_xlfn.MAP(_xlpm.srcRow,_xlfn.LAMBDA(_xlpm.sr,INDEX(O4:O200,_xlpm.sr))),_xlpm.ch,_xlfn.MAP(_xlpm.srcRow,_xlfn.LAMBDA(_xlpm.sr,INDEX(P4:P200,_xlpm.sr)+0)),_xlpm.instrStr,_xlfn.MAP(_xlpm.srcRow,_xlfn.LAMBDA(_xlpm.sr,INDEX(Q4:Q200,_xlpm.sr))),_xlpm.nInstr,_xlfn.MAP(_xlpm.srcRow,_xlfn.LAMBDA(_xlpm.sr,INDEX(R4:R200,_xlpm.sr)+0)),_xlpm.instrName,_xlfn.MAP(_xlpm.instrStr,_xlpm.instrIdx,_xlfn.LAMBDA(_xlpm.s,_xlpm.idx,TRIM(INDEX(_xlfn.TEXTSPLIT(_xlpm.s,"; "),,_xlpm.idx)))),_xlpm.ovAula,_xlfn.MAP(_xlpm.seq,_xlfn.LAMBDA(_xlpm.s,INDEX(U2:U200,_xlpm.s))),_xlpm.ovMat,_xlfn.MAP(_xlpm.seq,_xlfn.LAMBDA(_xlpm.s,INDEX(V2:V200,_xlpm.s))),_xlpm.geccAula,_xlfn.MAP(_xlpm.ovAula,_xlpm.ch,_xlfn.LAMBDA(_xlpm.ov,_xlpm.c,IF(_xlpm.ov<>"",_xlpm.ov+0,_xlpm.c))),_xlpm.geccMat,_xlfn.MAP(_xlpm.ovMat,_xlpm.ch,_xlpm.nInstr,_xlfn.LAMBDA(_xlpm.ov,_xlpm.c,_xlpm.n,IF(_xlpm.ov<>"",_xlpm.ov+0,_xlpm.c*0.3/_xlpm.n))),_xlpm.geccTotal,_xlpm.geccAula+_xlpm.geccMat,_xlfn.HSTACK(_xlpm.ano,_xlpm.id,_xlpm.status,_xlpm.curso,_xlpm.ch,_xlpm.instrName,_xlpm.nInstr,_xlpm.geccAula,_xlpm.geccMat,_xlpm.geccTotal))} -> 2026 | B2: 2026-001 | C2: Realizado | D2: Contratação de TIC | E2: 8 | F2: Flávio José Fonseca de Souza | G2: 1 | H2: 8 | I2: 2.4 | J2: 10.4
A3: 2026 | B3: 2026-002 | C3: Realizado | D3: Tcendo o Futuro - Edição Especial Filhos | E3: 4 | F3: Cinthia Thais de Carvalho Luz Thomazi | G3: 5 | H3: 4 | I3: 0.24 | J3: 4.24 | L3: fAno | M3: fID | N3: fStatus | O3: fCurso | P3: fCH | Q3: fInstr | R3: fNInstr | S3: fCumSum | T3: preCum
A4: 2026 | B4: 2026-002 | C4: Realizado | D4: Tcendo o Futuro - Edição Especial Filhos | E4: 4 | F4: Adriana Cuoco Portugal | G4: 5 | H4: 4 | I4: 0.24 | J4: 4.24 | L4: {=_xlfn.LET(_xlpm.src,'Ações InCompany'!A2:T1000,_xlpm.sAno,INDEX(_xlpm.src,,2),_xlpm.sMod,INDEX(_xlpm.src,,11),_xlfn._xlws.FILTER(_xlfn.HSTACK(INDEX(_xlpm.src,,2),INDEX(_xlpm.src,,1),INDEX(_xlpm.src,,3),INDEX(_xlpm.src,,5),INDEX(_xlpm.src,,19),INDEX(_xlpm.src,,20)),(_xlpm.sAno=M1)*(_xlpm.sMod="Instrutoria Interna"),""))} -> 2026 | M4: 2026-001 | N4: Realizado | O4: Contratação de TIC | P4: 8 | Q4: Flávio José Fonseca de Souza | R4: {=IF(L4:L200="","",IF(ISERROR(FIND("; ",Q4:Q200)),1,(LEN(Q4:Q200)-LEN(SUBSTITUTE(Q4:Q200,"; ","")))/2+1))} -> 1 | S4: {=IF(R4:R200="","",_xlfn.SCAN(0,R4:R200,_xlfn.LAMBDA(_xlpm.a,_xlpm.b,IF(_xlpm.b="","",_xlpm.a+_xlpm.b))))} -> 1 | T4: {=_xlfn.VSTACK(0,_xlfn._xlws.FILTER(S4:S200,S4:S200<>""))} -> 0
A5: 2026 | B5: 2026-002 | C5: Realizado | D5: Tcendo o Futuro - Edição Especial Filhos | E5: 4 | F5: Fernanda Viana de Souza | G5: 5 | H5: 4 | I5: 0.24 | J5: 4.24 | L5: 2026 | M5: 2026-002 | N5: Realizado | O5: Tcendo o Futuro - Edição Especial Filhos | P5: 4 | Q5: Cinthia Thais de Carvalho Luz Thomazi; Adriana Cuoco Portugal; Fernanda Viana de Souza; Denise Duarte Guirra Kuhlmann; Priscila Nolasco | R5: 5 | S5: 6 | T5: 1
A6: 2026 | B6: 2026-002 | C6: Realizado | D6: Tcendo o Futuro - Edição Especial Filhos | E6: 4 | F6: Denise Duarte Guirra Kuhlmann | G6: 5 | H6: 4 | I6: 0.24 | J6: 4.24 | L6: 2026 | M6: 2026-004 | N6: Realizado | O6: Gestão e Fiscalização de Contratos de Equipamentos Médico Hospitalares e Serviços de Manutenção | P6: 12 | Q6: Tarsila Firmino Ely; Luciana Alvim | R6: 2 | S6: 8 | T6: 6
A7: 2026 | B7: 2026-002 | C7: Realizado | D7: Tcendo o Futuro - Edição Especial Filhos | E7: 4 | F7: Priscila Nolasco | G7: 5 | H7: 4 | I7: 0.24 | J7: 4.24 | L7: 2026 | M7: 2026-005 | N7: Realizado | O7: FIT1: Treinamento e Desenvolvimento (T&D) | P7: 16 | Q7: Paulo José Góes Daltro | R7: 1 | S7: 9 | T7: 8
A8: 2026 | B8: 2026-004 | C8: Realizado | D8: Gestão e Fiscalização de Contratos de Equipamentos Médico Hospitalares e Serviços de Manutenção | E8: 12 | F8: Tarsila Firmino Ely | G8: 2 | H8: 12 | I8: 1.8 | J8: 13.8 | L8: 2026 | M8: 2026-006 | N8: Realizado | O8: Curso para gestores e fiscais de contratos de serviços assistenciais complementares – SES/DF | P8: 12 | Q8: Adriana Magalhães; Luciana Alvim | R8: 2 | S8: 11 | T8: 9
A9: 2026 | B9: 2026-004 | C9: Realizado | D9: Gestão e Fiscalização de Contratos de Equipamentos Médico Hospitalares e Serviços de Manutenção | E9: 12 | F9: Luciana Alvim | G9: 2 | H9: 12 | I9: 1.8 | J9: 13.8 | L9: 2026 | M9: 2026-007 | N9: Realizado | O9: Planilhas de Terceirização de Mão de Obra, de acordo com a Lei nº 14.133/2021 - T1 | P9: 20 | Q9: Leonardo José Alves Leal Neri | R9: 1 | S9: 12 | T9: 11
A10: 2026 | B10: 2026-005 | C10: Realizado | D10: FIT1: Treinamento e Desenvolvimento (T&D) | E10: 16 | F10: Paulo José Góes Daltro | G10: 1 | H10: 0 | I10: 0 | J10: 0 | L10: 2026 | M10: 2026-008 | N10: Realizado | O10: Curso de Promoção Funcional 2026/2027 | P10: 20 | Q10: Rômulo Miranda Alvim; Cinthia Thais de Carvalho Luz Thomazi | R10: 2 | S10: 14 | T10: 12 | U10: 0 | V10: 0
A11: 2026 | B11: 2026-006 | C11: Realizado | D11: Curso para gestores e fiscais de contratos de serviços assistenciais complementares – SES/DF | E11: 12 | F11: Adriana Magalhães | G11: 2 | H11: 12 | I11: 1.8 | J11: 13.8 | L11: 2026 | M11: 2026-009 | N11: Realizado | O11: Introdução à Engenharia de Prompt - t1 | P11: 8 | Q11: Arthur Wú; Gustavo Takahashi | R11: 2 | S11: 16 | T11: 14
A12: 2026 | B12: 2026-006 | C12: Realizado | D12: Curso para gestores e fiscais de contratos de serviços assistenciais complementares – SES/DF | E12: 12 | F12: Luciana Alvim | G12: 2 | H12: 12 | I12: 1.8 | J12: 13.8 | L12: 2026 | M12: 2026-010 | N12: Realizado | O12: Planilhas de Terceirização de Mão de Obra, de acordo com a Lei nº 14.133/2021 - T2 | P12: 20 | Q12: Leonardo José Alves Leal Neri | R12: 1 | S12: 17 | T12: 16
A13: 2026 | B13: 2026-007 | C13: Realizado | D13: Planilhas de Terceirização de Mão de Obra, de acordo com a Lei nº 14.133/2021 - T1 | E13: 20 | F13: Leonardo José Alves Leal Neri | G13: 1 | H13: 20 | I13: 6 | J13: 26 | L13: 2026 | M13: 2026-013 | N13: A realizar | O13: Introdução à Engenharia de Prompt - t2 | P13: 8 | Q13: Arthur Wú; Gustavo Takahashi | R13: 2 | S13: 19 | T13: 17
A14: 2026 | B14: 2026-008 | C14: Realizado | D14: Curso de Promoção Funcional 2026/2027 | E14: 20 | F14: Rômulo Miranda Alvim | G14: 2 | H14: 20 | I14: 3 | J14: 23 | L14: 2026 | M14: 2026-014 | N14: A realizar | O14: Mostra Fotográfica “Meu Olhar sobre Brasília” | P14: 0 | Q14: Servidores, colaboradores e estagiários do TCDF | R14: 1 | S14: 20 | T14: 19
A15: 2026 | B15: 2026-008 | C15: Realizado | D15: Curso de Promoção Funcional 2026/2027 | E15: 20 | F15: Cinthia Thais de Carvalho Luz Thomazi | G15: 2 | H15: 20 | I15: 3 | J15: 23 | L15: 2026 | M15: 2026-015 | N15: A realizar | O15: Tcendo o Futuro | P15: 4 | Q15: Cinthia Thais de Carvalho Luz Thomazi; Adriana Cuoco Portugal; Fernanda Viana de Souza; Denise Duarte Guirra Kuhlmann; Priscila Nolasco | R15: 5 | S15: 25 | T15: 20
A16: 2026 | B16: 2026-009 | C16: Realizado | D16: Introdução à Engenharia de Prompt - t1 | E16: 8 | F16: Arthur Wú | G16: 2 | H16: 8 | I16: 1.2 | J16: 9.2 | L16: 2026 | M16: 2026-016 | N16: A realizar | O16: FIT1: Treinamento e Desenvolvimento (T&D) - T2 | P16: 16 | Q16: Paulo José Góes Daltro | R16: 1 | S16: 26 | T16: 25
A17: 2026 | B17: 2026-009 | C17: Realizado | D17: Introdução à Engenharia de Prompt - t1 | E17: 8 | F17: Gustavo Takahashi | G17: 2 | H17: 8 | I17: 1.2 | J17: 9.2 | L17: 2026 | M17: 2026-017 | N17: A realizar | O17: Fiscalizações Baseadas em Risco | P17: 20 | Q17: Larissa Vieira; Reinaldo Alencar; Rogério Ribeiro | R17: 3 | S17: 29 | T17: 26
A18: 2026 | B18: 2026-010 | C18: Realizado | D18: Planilhas de Terceirização de Mão de Obra, de acordo com a Lei nº 14.133/2021 - T2 | E18: 20 | F18: Leonardo José Alves Leal Neri | G18: 1 | H18: 20 | I18: 6 | J18: 26 | L18: 2026 | M18: 2026-018 | N18: A realizar | O18: Tcendo o Futuro | P18: 4 | Q18: Cinthia Thais de Carvalho Luz Thomazi; Adriana Cuoco Portugal; Fernanda Viana de Souza; Denise Duarte Guirra Kuhlmann; Priscila Nolasco | R18: 5 | S18: 34 | T18: 29
A19: 2026 | B19: 2026-013 | C19: A realizar | D19: Introdução à Engenharia de Prompt - t2 | E19: 8 | F19: Arthur Wú | G19: 2 | H19: 8 | I19: 1.2 | J19: 9.2 | L19: 2026 | M19: 2026-019 | N19: A realizar | O19: FIT1: Treinamento e Desenvolvimento (T&D) - T3 | P19: 16 | Q19: Paulo José Góes Daltro | R19: 1 | S19: 35 | T19: 34
A20: 2026 | B20: 2026-013 | C20: A realizar | D20: Introdução à Engenharia de Prompt - t2 | E20: 8 | F20: Gustavo Takahashi | G20: 2 | H20: 8 | I20: 1.2 | J20: 9.2 | T20: 35
A21: 2026 | B21: 2026-014 | C21: A realizar | D21: Mostra Fotográfica “Meu Olhar sobre Brasília” | E21: 0 | F21: Servidores, colaboradores e estagiários do TCDF | G21: 1 | H21: 0 | I21: 0 | J21: 0
A22: 2026 | B22: 2026-015 | C22: A realizar | D22: Tcendo o Futuro | E22: 4 | F22: Cinthia Thais de Carvalho Luz Thomazi | G22: 5 | H22: 4 | I22: 0.24 | J22: 4.24
A23: 2026 | B23: 2026-015 | C23: A realizar | D23: Tcendo o Futuro | E23: 4 | F23: Adriana Cuoco Portugal | G23: 5 | H23: 4 | I23: 0.24 | J23: 4.24
A24: 2026 | B24: 2026-015 | C24: A realizar | D24: Tcendo o Futuro | E24: 4 | F24: Fernanda Viana de Souza | G24: 5 | H24: 4 | I24: 0.24 | J24: 4.24
A25: 2026 | B25: 2026-015 | C25: A realizar | D25: Tcendo o Futuro | E25: 4 | F25: Denise Duarte Guirra Kuhlmann | G25: 5 | H25: 4 | I25: 0.24 | J25: 4.24
A26: 2026 | B26: 2026-015 | C26: A realizar | D26: Tcendo o Futuro | E26: 4 | F26: Priscila Nolasco | G26: 5 | H26: 4 | I26: 0.24 | J26: 4.24
A27: 2026 | B27: 2026-016 | C27: A realizar | D27: FIT1: Treinamento e Desenvolvimento (T&D) - T2 | E27: 16 | F27: Paulo José Góes Daltro | G27: 1 | H27: 0 | I27: 0 | J27: 0 | U27: 0 | V27: 0
A28: 2026 | B28: 2026-017 | C28: A realizar | D28: Fiscalizações Baseadas em Risco | E28: 20 | F28: Larissa Vieira | G28: 3 | H28: 20 | I28: 2 | J28: 22
A29: 2026 | B29: 2026-017 | C29: A realizar | D29: Fiscalizações Baseadas em Risco | E29: 20 | F29: Reinaldo Alencar | G29: 3 | H29: 20 | I29: 2 | J29: 22
A30: 2026 | B30: 2026-017 | C30: A realizar | D30: Fiscalizações Baseadas em Risco | E30: 20 | F30: Rogério Ribeiro | G30: 3 | H30: 20 | I30: 2 | J30: 22
A31: 2026 | B31: 2026-018 | C31: A realizar | D31: Tcendo o Futuro | E31: 4 | F31: Cinthia Thais de Carvalho Luz Thomazi | G31: 5 | H31: 4 | I31: 0.24 | J31: 4.24
A32: 2026 | B32: 2026-018 | C32: A realizar | D32: Tcendo o Futuro | E32: 4 | F32: Adriana Cuoco Portugal | G32: 5 | H32: 4 | I32: 0.24 | J32: 4.24
A33: 2026 | B33: 2026-018 | C33: A realizar | D33: Tcendo o Futuro | E33: 4 | F33: Fernanda Viana de Souza | G33: 5 | H33: 4 | I33: 0.24 | J33: 4.24
A34: 2026 | B34: 2026-018 | C34: A realizar | D34: Tcendo o Futuro | E34: 4 | F34: Denise Duarte Guirra Kuhlmann | G34: 5 | H34: 4 | I34: 0.24 | J34: 4.24
A35: 2026 | B35: 2026-018 | C35: A realizar | D35: Tcendo o Futuro | E35: 4 | F35: Priscila Nolasco | G35: 5 | H35: 4 | I35: 0.24 | J35: 4.24
A36: 2026 | B36: 2026-019 | C36: A realizar | D36: FIT1: Treinamento e Desenvolvimento (T&D) - T3 | E36: 16 | F36: Paulo José Góes Daltro | G36: 1 | H36: 0 | I36: 0 | J36: 0 | U36: 0 | V36: 0

Sheet Ações 2026
H4: AÇÕES EDUCACIONAIS 2026 CEDUC
B7: Trimestre | C7: Processo | D7: Supervisão | E7: Nome da Ação Educacional | F7: Status | G7: Qual fase? | H7: Data do Curso | I7: C.H. | J7: Modalidade Instrutoria | K7: Instrutores | L7: Vagas | M7: Inscritos | N7: Responsável
B8: 1º | C8: 14319/25 | D8: SAED | E8: Contratação de TIC | F8: Realizado | G8: Finalizado | H8: 20 e 21 de janeiro | I8: 8 | J8: Instrutoria Interna | K8: Flávio José Fonseca | L8: 50 | M8: 55 | N8: Stéphanie
B9: 1º | C9: 16298/25 | D9: SIPEC | E9: TCendo o Futuro - Edição Filhos | F9: Realizado | G9: Finalizado | H9: 23 de janeiro | I9: 4 | J9: Instrutoria Interna | K9: Diversos | L9: 30 | M9: 25 | N9: Raphael
B10: 1º | C10: 4926/25 | D10: SAED | E10: Estruturação de Inovações Disruptivas no TCDF | F10: Realizado | G10: Finalizado | H10: 26 a 30 de janeiro, 2,3, 4 de fevereiro; 9 e 10 fevereiro | I10: 42 | J10: Instrutoria Externa | K10: Caio Castelliano | L10: 30 | M10: 23 | N10: Paula
B11: 1º | C11: 15827/25 | D11: SAED | E11: Gestão e Fiscalização de Contratos de Equipamentos Médico Hospitalares e Serviços de Manutenção | F11: Realizado | G11: Finalizado | H11: 25 a 27 de fevereiro | I11: 12 | J11: Instrutoria Interna | K11: Tarsila Firmino; Luciana Alvim | L11: 20 | M11: 44 | N11: Taissa
B12: 1º | C12: 529/26 | D12: SAED | E12: FIT1: Treinamento e Desenvolvimento (T&D) | F12: Realizado | G12: Finalizado | H12: 25 a 27 de fevereiro; 2 de março | I12: 16 | J12: Instrutoria Interna | K12: Paulo José Góes Daltro | L12: 20 | M12: 18 | N12: Paula
B13: 1º | C13: 15352/25 | D13: SAED | E13: Curso para gestores e fiscais de contratos de serviços assistenciais complementares – SES/DF - T1 | F13: Realizado | G13: Finalizado | H13: 4 a 6 de março | I13: 12 | J13: Instrutoria Interna | K13: Adriana Magalhães; Luciana Rocha de Melo | L13: 20 | M13: 20 | N13: Taissa
B14: 1º | C14: 10/26 | D14: SAED | E14: Planilhas de Terceirização de Mão de Obra, de acordo com a Lei nº 14.133/2021 - T1 | F14: Realizado | G14: Aguardando finalizar doc T2 | H14: 9 a 13 de março | I14: 20 | J14: Instrutoria Interna | K14: Leonardo Leal Neri | L14: 20 | M14: 19 | N14: Paula
B15: 1º | C15: 354/26 | D15: SAED | E15: Promoção Funcional | F15: Realizado | G15: Relatório GECC pgmto encaminhado | H15: 16, 17, 19, 20 de março | I15: 20 | J15: Instrutoria Interna | K15: Rômulo Miranda Alvim; Cinthia Thais de Carvalho Luz Thomazi | L15: 33 | M15: 33 | N15: Stéphanie
B16: 1º | C16: 15249/2025 | D16: SAED | E16: Engenharia de Prompt - T1 | F16: Realizado | G16: Relatório GECC pgmto encaminhado | H16: 17 a 19 de março | I16: 8 | J16: Instrutoria Interna | K16: Arthur WÚ | L16: 20 | M16: 20 | N16: Stéphanie
B17: 1º | C17: 10/26 | D17: SAED | E17: Planilhas de Terceirização de Mão de Obra, de acordo com a Lei nº 14.133/2021 - T2 | F17: Realizado | G17: Aguardando AR e Lista Presença | H17: 23 a 27 de março | I17: 20 | J17: Instrutoria Interna | K17: Leonardo Leal Neri | L17: 20 | M17: 19 | N17: Paula
B18: 1º | C18: 2111/26 | D18: SAED | E18: Dia da Ouvidoria | F18: Realizado | G18: Autorizado | H18: 24 de março | I18: 4 | J18: Instrutoria Externa | K18: Diversos | L18: 170 | M18: 140 | N18: Gilson
B19: 1º | C19: 49/26 | D19: SAED | E19: Maratona de Transparência Pública | F19: Em andamento | G19: Aguardando AR e Lista Presença | H19: 30 e 31 de março | I19: 14 | J19: Instrutoria Externa | K19: Diversos | M19: 180 | N19: Sibele
B20: 2º | C20: 1984/26 | D20: SAED | E20: Curso para gestores e fiscais de contratos de serviços assistenciais complementares – SES/DF - Turma 2 | F20: A realizar | G20: Autorizado pela Presidência | H20: 8 a 10 de abril | I20: 12 | J20: Instrutoria Interna | K20: Adriana Magalhães; Luciana Rocha de Melo | L20: 20 | N20: Taissa
B21: 2º | D21: SIPEC | E21: Café e Tartúlia | F21: A realizar | H21: 10 de abril | I21: 4 | J21: Instrutoria Interna | K21: Diversos | N21: Raphael
B22: 2º | C22: 3976/25 | D22: SAED | E22: Curso de Formação para Conselheiros de Cultura | F22: A realizar | G22: Em processo de contratação | H22: 13 a 16 de abril | I22: 16 | J22: Instrutoria Externa | K22: Christiane Montes Ramírez | L22: 50 | N22: Taissa
B23: 2º | C23: 15249/2025 | D23: SAED | E23: Engenharia de Prompt - T2 | F23: A realizar | G23: Autorizado pela Presidência | H23: 15 e 17 de abril | I23: 8 | J23: Instrutoria Interna | K23: Arthur WÚ; Gustavo Takahashi | L23: 20 | N23: Stéphanie
B24: 2º | C24: 2511/26 | D24: SIPEC | E24: Mostra Fotográfica “Meu Olhar sobre Brasília” | F24: A realizar | H24: 20 a 30 de abril | I24: - | K24: - | N24: Raphael
B25: 2º | C25: 1900/26 | D25: SIPEC | E25: TCendo o Futuro | F25: A realizar | H25: 23 e 24 de abril | I25: 4 | K25: Diversos | L25: 80 | N25: Raphael
B26: 2º | C26: 3103/26 | D26: SAED | E26: FIT1: Treinamento e Desenvolvimento (T&D) - T2 | F26: A realizar | G26: Em processo de autorização | H26: 27 a 30 de abril | J26: Instrutoria Interna | K26: Paulo José Góes Daltro | L26: 15 | N26: Paula
B27: 2º | C27: 3103/26 | D27: SAED | E27: FIT1: Treinamento e Desenvolvimento (T&D) - T3 | F27: A realizar | G27: Em processo de autorização | H27: 27 a 30 de abril | I27: 16 | J27: Instrutoria Interna | K27: Paulo José Góes Daltro | L27: 15 | N27: Paula
B28: 2º | D28: SAED | E28: Fiscalizações Baseadas em Risco | F28: A realizar | G28: Aguardando Solicitação | H28: 4, 5, 6, 11 e 12 de maio | I28: 20 | J28: Instrutoria Interna | K28: Rogério Ribeiro; Reinaldo Alencar; Larissa Vieira | L28: 20 | N28: Stéphanie
B29: 2º | C29: 1900/26 | D29: SIPEC | E29: TCendo o Futuro | F29: A realizar | H29: 8 de maio | I29: 4 | J29: Instrutoria Interna | K29: Diversos | L29: 80 | N29: Raphael
B30: 2º | C30: 2647/26 | D30: SAED | E30: Fórum Longevidade - Palestra Alexandre Kalache | F30: A realizar | H30: 21 e 22 de maio | I30: 1 | J30: Instrutoria Externa | K30: Alexandre Kalache | N30: Sibele
B31: 2º | C31: 2960/26 | D31: SAED | E31: Fórum Longevidade - Palestra Juliana | F31: A realizar | H31: 21 e 22 de maio | I31: 1 | J31: Instrutoria Externa | K31: Juliana Seild | N31: Stéphanie
B32: 2º | C32: 2820/26 | D32: SAED | E32: Fórum Longevidade - Escape Game | F32: A realizar | H32: 21 e 22 de maio | I32: 1 | J32: Instrutoria Externa | K32: Empresa Escape Game | N32: Paula
B33: 2º | C33: 3105/26 | D33: SAED | E33: Fórum Longevidade - Palestra Raquel | F33: A realizar | H33: 21 e 22 de maio | I33: 1 | J33: Instrutoria Externa | K33: Raquel Arigony | N33: Stéphanie
B34: 2º | C34: - | D34: SAED | E34: Políticas Públicas | F34: A realizar | G34: Elaborando Plano de Ensino | H34: 25 a 27 de maio; 1 a 3 de junho | I34: 20 | J34: Instrutoria Interna | K34: Rogério Ribeiro; Reinaldo Alencar | L34: 24 | N34: Stéphanie

Sheet Controle Arq.
G2: 11565/2024
G3: 13950/2023
G4: 784/2024
G5: 12891/2023
G6: 613/2024
G7: 6589/2024
G8: 6295/2024
G9: 920/2024
G10: 8683/2024
G11: 10049/2024
G12: 10118/2024
G13: 11946/2024 | I13: Paula
G14: 6564/2024
G15: 6321/2024
G16: 2928/2024
G17: 9914/2024
G18: 12138/2024
G19: 2524/2024 | M19: 00600-00006259/2022-18
G20: 5803/2024 | M20: 00600-00004891/2022-19
G21: 7023/2024 | M21: 3643/22
G22: 11896/2024 | M22: 3052/22
G23: 5036/2024 | M23: 3028/22
G24: 4375/2024 | M24: 2911/22
G25: 9044/2024 | M25: 2829/22
G26: 9074/2024 | M26: 2221/22
G27: 397/2024 | M27: 937/22
G28: 4734/2024 | M28: 12718/22
G29: 419/2024 | M29: 9809/21
G30: 1347/2024 | M30: 9715/21
... G41: 11097/2024 | M41: 3904/23
G42: 10889/2024 | I42: Pimenta | M42: 2178/23
G43: 10895/2024 | M43: 535/23
G44: 10896/2024 | M44: 402/23
G45: 10897/2024 | M45: 381/23
G46: 10898/2024 | M46: 14663/22
G47: 10901/2024 | M47: 13772/22
G48: 13257/2024 | M48: 13693/22
G49: 1125/2024 | M49: 11400/22
G50: 1401/2024 | M50: 11363/22
G51: 3829/2024 | M51: 9843/22
...

Sheet PlanoCap2627
A1: ANO - VIGÊNCIA | B1: EIXO TEMÁTICO | C1: Programa | D1: Público-Alvo Preferencial | E1: Descrição
A2: 2026/2027 | B2: Controle Externo | C2: Metodologias de Auditoria e Fiscalização | D2: Membros e servidores que atuam no Controle Externo | E2: Destina-se a oferecer ações de aprendizagem de metodologias necessárias à realização de fiscalizações governamentais, alinhadas às Normas Brasileiras de Auditoria do Setor Público
A3: 2026/2027 | B3: Controle Externo | C3: Áreas Temáticas de Fiscalização do Setor Público | D3: Membros e servidores que atuam no Controle Externo | E3: Destina-se a oferecer ações de aprendizagem voltadas às áreas temáticas fiscalizadas, como saúde, pessoal, previdência, assistência social, obras e serviços de engenharia, tecnologia da informação e comunicação, licitações e contratos, parcerias público-privadas, concessões e desestatização, entre outras
A4: 2026/2027 | B4: Controle Externo | C4: Treinamento de Jurisdicionados | D4: Servidores Públicos dos órgãos jurisdicionados ao TCDF | E4: Destina-se a oferecer ações de aprendiza_x0002_gem para os gestores e servidores públicos dos órgãos jurisdicionados ao TCDF, a fim de promover a correta e eficiente aplicação dos recursos públicos
A5: 2026/2027 | B5: Controle Externo | C5: Treinamento em Saúde Pública | D5: Membros e servidores do TCDF, servidores públicos dos órgãos jurisdicionados ao TCDF da área da saúde e cidadãos interessados na temática de saúde pública | E5: Destina-se a oferecer ações de aprendiza_x0002_gem para os atores responsáveis pela saúde pública distrital e interessados na temática, com vistas à correta e eficiente aplicação dos recursos públicos e à melhoria dos resultados do setor
A6: 2026/2027 | B6: Controle Externo | C6: Formação de Controladores sociais e cidadãos | D6: Representantes de entidades de Controle social e Cidadãos | E6: Destina-se a oferecer ações de aprendizagem para os cidadãos, para fomentar o exercício do controle social.
A7: 2026/2027 | B7: Organizacional | C7: Inteligência Artificial e Análise de Dados | D7: Membros e servidores do TCDF | E7: Destina-se a oferecer ações de aprendizagem voltadas ao uso da inteligência artificial e à análise e mineração de dados, a fim de iden_x0002_tificar informações úteis à tomada de decisão em meio a grandes quantidades de dados.
A8: 2026/2027 | B8: Organizacional | C8: Administração, Estratégia e Inovação | D8: Membros e Servidores do TCDF | E8: Destina-se a oferecer ações de aprendizagem para auxiliar na gestão e apoio estratégico do TCDF, assim como promover a inovação na Casa. As ações buscam aprimorar processos como os de planejamento, gestão de pessoas, gestão da informação, gestão de projetos, gestão de processos, gestão administrativa, gestão contratual, relacionamento com o cliente, operacionalização de sistemas, entre outros
A9: 2026/2027 | B9: Organizacional | C9: Escola de Instrutores | D9: Corpo técnico e docente da Escola de Contas Públicas do TCDF | E9: Destina-se a oferecer ações de aprendizagem para o corpo técnico e docente da Escola de Contas Públicas do TCDF, a fim de aprimorar a qualidade instrucional e os resultados das ações de treinamento oferecidas internamente.
A10: 2026/2027 | B10: Transversal | C10: Desenvolvimento de Líderes | D10: Servidores que ocu_x0002_pam função gerencial e potenciais líderes a desenvolver | E10: Destina-se a oferecer ações de aprendizagem para os atuais dirigentes do TCDF, consideran_x0002_do as necessidades de cada nível gerencial (estratégico, tático e operacional), àqueles que assumem funções gerenciais e aos servido_x0002_res com potencial de atuação gerencial no Tribunal. As ações devem auxiliar os gestores no exercício da função gerencial, aprimoran_x0002_do competências relacionadas à gestão de desempenho, ao desenvolvimento da equipe, à gestão de equipes remotas e/ou híbridas, à orientação estratégica, ao feedback, entre outras
A11: 2026/2027 | B11: Transversal | C11: Desenvolvimento Individual e Promoção da Cultura Organizacional | D11: Servidores do TCDF | E11: Destina-se a oferecer ações de aprendizagem para auxiliar no desenvolvimento de competências funcionais dos servidores, tais quais orientação para resultado, ética e relacionamento interpessoal.
A12: 2026/2027 | B12: Transversal | C12: Ambientação e Desenvolvimento na Carreira | D12: Servidores do TCDF | E12: Destina-se a oferecer ações de aprendizagem para auxiliar na ambientação e promoção de servidores, promovendo a visão sistêmica da sua atuação no âmbito do TCDF

Sheet Dashboard GECC 2026
A1: Dashboard GECC 2026 - Horas por Instrutor
A2: Consulta de horas GECC por instrutor em 2026
A4: Instrutor | B4: GECC Aula (h) | C4: GECC Material (h) | D4: Total GECC (h) | E4: Qtd Ações
A5: Leonardo José Alves Leal Neri | B5: =SUMIFS('GECC 2026'!H$2:H$200,'GECC 2026'!F$2:F$200,$A5) -> 40 | C5: =SUMIFS('GECC 2026'!I$2:I$200,'GECC 2026'!F$2:F$200,$A5) -> 12 | D5: =SUMIFS('GECC 2026'!J$2:J$200,'GECC 2026'!F$2:F$200,$A5) -> 52 | E5: =COUNTIFS('GECC 2026'!F$2:F$200,$A5) -> 2
A6: Luciana Alvim | B6: =SUMIFS('GECC 2026'!H$2:H$200,'GECC 2026'!F$2:F$200,$A6) -> 24 | C6: =SUMIFS('GECC 2026'!I$2:I$200,'GECC 2026'!F$2:F$200,$A6) -> 3.6 | D6: =SUMIFS('GECC 2026'!J$2:J$200,'GECC 2026'!F$2:F$200,$A6) -> 27.6 | E6: =COUNTIFS('GECC 2026'!F$2:F$200,$A6) -> 2
A7: Cinthia Thais de Carvalho Luz Thomazi | B7: =SUMIFS('GECC 2026'!H$2:H$200,'GECC 2026'!F$2:F$200,$A7) -> 32 | C7: =SUMIFS('GECC 2026'!I$2:I$200,'GECC 2026'!F$2:F$200,$A7) -> 3.72 | D7: =SUMIFS('GECC 2026'!J$2:J$200,'GECC 2026'!F$2:F$200,$A7) -> 35.72 | E7: =COUNTIFS('GECC 2026'!F$2:F$200,$A7) -> 4
A8: Rômulo Miranda Alvim | B8: =SUMIFS('GECC 2026'!H$2:H$200,'GECC 2026'!F$2:F$200,$A8) -> 20 | C8: =SUMIFS('GECC 2026'!I$2:I$200,'GECC 2026'!F$2:F$200,$A8) -> 3 | D8: =SUMIFS('GECC 2026'!J$2:J$200,'GECC 2026'!F$2:F$200,$A8) -> 23 | E8: =COUNTIFS('GECC 2026'!F$2:F$200,$A8) -> 1
A9: Larissa Vieira | B9: =SUMIFS('GECC 2026'!H$2:H$200,'GECC 2026'!F$2:F$200,$A9) -> 20 | C9: =SUMIFS('GECC 2026'!I$2:I$200,'GECC 2026'!F$2:F$200,$A9) -> 2 | D9: =SUMIFS('GECC 2026'!J$2:J$200,'GECC 2026'!F$2:F$200,$A9) -> 22 | E9: =COUNTIFS('GECC 2026'!F$2:F$200,$A9) -> 1
A10: Reinaldo Alencar | B10: =SUMIFS('GECC 2026'!H$2:H$200,'GECC 2026'!F$2:F$200,$A10) -> 20 | C10: =SUMIFS('GECC 2026'!I$2:I$200,'GECC 2026'!F$2:F$200,$A10) -> 2 | D10: =SUMIFS('GECC 2026'!J$2:J$200,'GECC 2026'!F$2:F$200,$A10) -> 22 | E10: =COUNTIFS('GECC 2026'!F$2:F$200,$A10) -> 1
A11: Rogério Ribeiro | B11: =SUMIFS('GECC 2026'!H$2:H$200,'GECC 2026'!F$2:F$200,$A11) -> 20 | C11: =SUMIFS('GECC 2026'!I$2:I$200,'GECC 2026'!F$2:F$200,$A11) -> 2 | D11: =SUMIFS('GECC 2026'!J$2:J$200,'GECC 2026'!F$2:F$200,$A11) -> 22 | E11: =COUNTIFS('GECC 2026'!F$2:F$200,$A11) -> 1
A12: Paulo José Góes Daltro | B12: =SUMIFS('GECC 2026'!H$2:H$200,'GECC 2026'!F$2:F$200,$A12) -> 0 | C12: =SUMIFS('GECC 2026'!I$2:I$200,'GECC 2026'!F$2:F$200,$A12) -> 0 | D12: =SUMIFS('GECC 2026'!J$2:J$200,'GECC 2026'!F$2:F$200,$A12) -> 0 | E12: =COUNTIFS('GECC 2026'!F$2:F$200,$A12) -> 3
A13: Arthur Wú | B13: =SUMIFS('GECC 2026'!H$2:H$200,'GECC 2026'!F$2:F$200,$A13) -> 16 | C13: =SUMIFS('GECC 2026'!I$2:I$200,'GECC 2026'!F$2:F$200,$A13) -> 2.4 | D13: =SUMIFS('GECC 2026'!J$2:J$200,'GECC 2026'!F$2:F$200,$A13) -> 18.4 | E13: =COUNTIFS('GECC 2026'!F$2:F$200,$A13) -> 2
A14: Gustavo Takahashi | B14: =SUMIFS('GECC 2026'!H$2:H$200,'GECC 2026'!F$2:F$200,$A14) -> 16 | C14: =SUMIFS('GECC 2026'!I$2:I$200,'GECC 2026'!F$2:F$200,$A14) -> 2.4 | D14: =SUMIFS('GECC 2026'!J$2:J$200,'GECC 2026'!F$2:F$200,$A14) -> 18.4 | E14: =COUNTIFS('GECC 2026'!F$2:F$200,$A14) -> 2
A15: Adriana Magalhães | B15: =SUMIFS('GECC 2026'!H$2:H$200,'GECC 2026'!F$2:F$200,$A15) -> 12 | C15: =SUMIFS('GECC 2026'!I$2:I$200,'GECC 2026'!F$2:F$200,$A15) -> 1.8 | D15: =SUMIFS('GECC 2026'!J$2:J$200,'GECC 2026'!F$2:F$200,$A15) -> 13.8 | E15: =COUNTIFS('GECC 2026'!F$2:F$200,$A15) -> 1
A16: Tarsila Firmino Ely | B16: =SUMIFS('GECC 2026'!H$2:H$200,'GECC 2026'!F$2:F$200,$A16) -> 12 | C16: =SUMIFS('GECC 2026'!I$2:I$200,'GECC 2026'!F$2:F$200,$A16) -> 1.8 | D16: =SUMIFS('GECC 2026'!J$2:J$200,'GECC 2026'!F$2:F$200,$A16) -> 13.8 | E16: =COUNTIFS('GECC 2026'!F$2:F$200,$A16) -> 1
... A22: Servidores, colaboradores e estagiários do TCDF | B22: =SUMIFS('GECC 2026'!H$2:H$200,'GECC 2026'!F$2:F$200,$A22) -> 0 | C22: =SUMIFS('GECC 2026'!I$2:I$200,'GECC 2026'!F$2:F$200,$A22) -> 0 | D22: =SUMIFS('GECC 2026'!J$2:J$200,'GECC 2026'!F$2:F$200,$A22) -> 0 | E22: =COUNTIFS('GECC 2026'!F$2:F$200,$A22) -> 1
A24: TOTAL GERAL | B24: =SUM(B5:B22) -> 288 | C24: =SUM(C5:C22) -> 42 | D24: =SUM(D5:D22) -> 330 | E24: =SUM(E5:E22) -> 35

Sheet legado
A1: ID_TIPO | B1: Exerc. | C1: Previsão | D1: Status Evento | E1: Processo | F1: Temática | G1: DESTAQUE | H1: Descrição Dest. | I1: Público-Alvo | J1: Programa | K1: TIPO ESCON | L1: Data TXT | M1: Início | N1: Término | O1: Modalidade | P1: Valor Insc. | Q1: V. Coffee Break | R1: Nota Av. Reação | S1: %Av. Reação | T1: Qtd Vagas | U1: P. Servidores | V1: P. Jurisdicionados | W1: P. Sociedade | X1: Total Part. | Y1: C.H. | Z1: Mikhail | AA1: Instrutor | AB1: Objetivo Geral | AC1: Coluna1 | AD1: Coluna2
A2: InCompany | B2: 2014 | D2: Realizado | F2: CURSO DE ELABORAÇÃO DE PARECERES E RELATÓRIOS | I2: Controle Externo | J2: C.E - Programa de Auditoria e Fiscalização do Setor Público | L2: 17 a 21/03/2014 | M2: 41715 | N2: 41719 | O2: Instrutoria Externa | P2: 19500 | U2: 20 | X2: =SUM(U2:W2) -> 20 | Y2: 20
A3: InCompany | B3: 2014 | D3: Realizado | F3: ELABORAÇÃO DE PLANO DE AUDITORIA E MATRIZ DE PLANEJAMENTO | I3: Controle Externo | J3: C.E - Programa de Auditoria e Fiscalização do Setor Público | L3: 14 e 14/04/2014 | M3: 41743 | N3: 41744 | O3: Instrutoria Externa | P3: 28000 | U3: 16 | X3: =SUM(U3:W3) -> 16 | Y3: 16
A4: InCompany | B4: 2014 | D4: Realizado | F4: CURSO DE EXCEL AVANÇADO | I4: Áreas Administrativas | J4: A.C.E - Programa de Análise de Dados | L4: 02 a 09/06/2014 | M4: 41792 | N4: 41799 | O4: Instrutoria Interna | P4: 2991 | U4: 24 | X4: =SUM(U4:W4) -> 24 | Y4: 24
A5: InCompany | B5: 2014 | D5: Realizado | F5: REGIME DIFERENCIADO DE CONTRATAÇÕES PÚBLICAS - RDC | I5: Controle Externo | J5: C.E - Programa de Orçamento e Finanças Públicas | L5: 24 e 25/06/2014 | M5: 41814 | N5: 41815 | O5: Instrutoria Externa | P5: 41341.16 | U5: 16 | X5: =SUM(U5:W5) -> 16 | Y5: 16
A6: InCompany | B6: 2014 | D6: Realizado | F6: ENGENHARIA ECONÔMICA I E II - CAPACITAÇÃO EM PARCERIAS PÚBLICO PRIVADAS E CONCESSÕES DE | I6: Controle Externo | J6: C.E - Programa de Auditoria e Fiscalização do Setor Público | L6: 04 a 08/08/2014 | M6: 41855 | N6: 41859 | O6: Instrutoria Externa | P6: 54900 | U6: 40 | X6: =SUM(U6:W6) -> 40 | Y6: 40
A7: InCompany | B7: 2014 | D7: Realizado | F7: CURSO TÉCNICAS DE AUDITORIA OPERACIONAL | I7: Controle Externo | J7: C.E - Programa de Auditoria e Fiscalização do Setor Público | L7: 10/09/2014 | M7: 41892 | N7: 41892 | O7: Instrutoria Externa | P7: 15000 | U7: 30 | X7: =SUM(U7:W7) -> 30 | Y7: 30
A8: InCompany | B8: 2014 | D8: Realizado | F8: 05, 12, 19 e 26 de abril de 2024, de 14h às 18h. | I8: Controle Externo | J8: C.E - Programa de Auditoria e Fiscalização do Setor Público | L8: 31/10/2014 | M8: 41943 | N8: 41943 | O8: Instrutoria Externa | P8: 33260 | U8: 24 | X8: =SUM(U8:W8) -> 24 | Y8: 24
A9: InCompany | B9: 2014 | D9: Realizado | F9: PROCESSO DE CONTRATAÇÃO PÚBLICA | I9: Controle Externo | J9: C.E - Programa de Orçamento e Finanças Públicas | L9: 10 a 14/11/2014 | M9: 41953 | N9: 41957 | O9: Instrutoria Interna | P9: 4353.54 | V9: 37 | X9: =SUM(U9:W9) -> 37 | Y9: 8
A10: InCompany | B10: 2014 | D10: Realizado | F10: TERMO DE REFERÊNCIA DE SERVIÇOS CONTINUADOS COM DEDICAÇÃO EXCLUSIVA DE MÃO DE OBRA | I10: Controle Externo | J10: C.E - Programa de Auditoria e Fiscalização do Setor Público | L10: 24 a 28/11/2014 | M10: 41967 | N10: 41971 | O10: Instrutoria Interna | P10: 4353.54 | V10: 58 | X10: =SUM(U10:W10) -> 58 | Y10: 20
A11: InCompany | B11: 2015 | D11: Realizado | E11: 1683/2015 | F11: ELABORAÇÃO DE PARECERES E RELATÓRIOS | I11: Controle Externo | J11: C.E - Programa de Auditoria e Fiscalização do Setor Público | L11: 23 a 27/03/2015 | M11: 42086 | N11: 42090 | O11: Instrutoria Externa | P11: 23500 | U11: 25 | X11: =SUM(U11:W11) -> 25 | Y11: 20 | AA11: José Paulo Moreira de Oliveira
A12: InCompany | B12: 2015 | D12: Realizado | E12: 3716/2015 | F12: O PROCESSO DE CONTRATAÇÃO PÚBLICA | I12: Jurisdicionados | J12: C.E - Programa de Orçamento e Finanças Públicas | L12: 06 a 10/04/2015 | M12: 42100 | N12: 42104 | O12: Instrutoria Interna | P12: 4992.74 | V12: 85 | X12: =SUM(U12:W12) -> 85 | Y12: 20 | AA12: Amauri Alves Nery
A13: InCompany | B13: 2015 | D13: Realizado | E13: 2515/2015 | F13: TERMO DE REFERÊNCIA DE SERVIÇOS CONTINUADOS COM DEDICAÇÃO EXCLUSIVA DE MÃO DE OBRA | I13: Jurisdicionados | J13: C.E - Programa de Capacitação para Jurisdicionados Controladores sociais e Cidadãos | L13: 13 a 17/04/2015 | M13: 42107 | N13: 42111 | O13: Instrutoria Interna | P13: 4447.52 | V13: 89 | X13: =SUM(U13:W13) -> 89 | Y13: 20 | AA13: LEONARDO JOSE ALVES LEAL NERI
A14: InCompany | B14: 2015 | D14: Realizado | E14: 7690/2015 | F14: FISCALIZAÇÃO DE CONTRATOS ADMINISTRATIVOS | I14: Áreas Administrativas | J14: A.C.E - Programa de Gestão e Estratégia | L14: 16, 17, 22, 23 e 24/04/2020 | M14: 42110 | N14: 42118 | O14: Instrutoria Interna | P14: 4447.52 | U14: 37 | X14: =SUM(U14:W14) -> 37 | Y14: 30 | AA14: LEONARDO JOSE ALVES LEAL NERI
A15: InCompany | B15: 2015 | D15: Realizado | F15: PALESTRA CONSELHOS REGIONAIS DE SAÚDE | I15: Sociedade | J15: N/A | M15: 42122 | N15: 42122 | O15: Instrutoria Interna | P15: 0 | X15: =SUM(U15:W15) -> 0 | Y15: 5
A16: InCompany | B16: 2015 | D16: Realizado | E16: 3481/2015 | F16: PROCESSO NOS TRIBUNAIS DE CONTAS | I16: Controle Externo | J16: C.E - Programa de Auditoria e Fiscalização do Setor Público | L16: 26 a 29/05/2015 | M16: 42129 | N16: 42132 | O16: Instrutoria Externa | P16: 35500 | U16: 30 | X16: =SUM(U16:W16) -> 30 | Y16: 16 | AA16: Odilon Cavallari de Oliveira
A17: InCompany | B17: 2015 | D17: Realizado | E17: 5654/2015 | F17: A NOVA CONTABILIDADE APLICADA AO SETOR PÚBLICO | I17: Áreas Administrativas | J17: A.C.E - Programa de Gestão e Estratégia | L17: 11 a 15/05/2015 | M17: 42135 | N17: 42139 | O17: Instrutoria Interna | P17: 4992.74 | U17: 30 | X17: =SUM(U17:W17) -> 30 | Y17: 20 | AA17: ROMILDO ARAUJO DA SILVA
A18: InCompany | B18: 2015 | D18: Realizado | E18: 14060/2015 | F18: TREINAMENTO DO SISTEMA TERRAGEO | I18: Áreas Administrativas | J18: A.C.E - Programa de Gestão e Estratégia | L18: 22/05/2015 | M18: 42146 | N18: 42146 | O18: Instrutoria Externa | P18: 0 | U18: 15 | X18: =SUM(U18:W18) -> 15 | Y18: 8 | AA18: INSTRUTOR EXTERNO TERRACAP
A19: InCompany | B19: 2015 | D19: Realizado | E19: 1098/2015 | F19: EXCEL AVANÇADO | I19: Áreas Administrativas | J19: A.C.E - Programa de Análise de Dados | L19: 25/05/2015 01/06/2015 | M19: 42149 | N19: 42156 | O19: Instrutoria Externa | P19: 2630 | U19: 14 | X19: =SUM(U19:W19) -> 14 | Y19: 24 | AA19: Logus TI
A20: InCompany | B20: 2015 | D20: Realizado | E20: 12742/2015 | F20: TREINAMENTO SIGGO (Sistema Integrado de Contabilidade Governamental) | I20: Áreas Administrativas | J20: C.E - Programa de Orçamento e Finanças Públicas | L20: 08 a 12/06/2015 | M20: 42163 | N20: 42167 | O20: Instrutoria Interna | P20: 0 | U20: 14 | X20: =SUM(U20:W20) -> 14 | Y20: 20 | AA20: ROMULO MIRANDA ALVIM
